#dig label(dig),,,,,,,,,,,,,
h,,,,,,,,,,,,,h
h,,,,,,,,,,,,,h
h,,,,,,,,,,,,,h
h,,,,,,,,,,,,,h
#>,,,,,,,,,,,,,
r,d,h,,,,,,,,,h,d,r
r,d,h,,,,,,,,,h,d,r
r,d,h,,,,,,,,,h,d,r
r,d,h,,,,,,,,,h,d,r
#>,,,,,,,,,,,,,
,,r,d,d,d,d,d,d,d,d,r,,
,,r,d,d,d,d,d,d,d,d,r,,
,,r,d,d,d,d,d,d,d,d,r,,
,,r,d,d,d,d,d,d,d,d,r,,
